Workbook

Sheet 除外曲
B2: 除外曲 455曲 | J2: 追加希望 | K2: =SUMPRODUCT(--F7:F461) -> 192
A3: 追加したい曲は「追加希望」列のチェックボックスをクリックしてください。
A4: 発売日は歌ネット掲載値。初出日とは異なる再発売日が使われている場合があります。
A6: 元順位 | B6: 曲名 | C6: アーティスト | D6: 掲載発売日 | E6: 除外理由 | F6: 追加希望 | G6: 追加時の段位 | H6: 曲ページ
A7: 6 | B7: キセキ | C7: GReeeeN | D7: 39596 | E7: 2010年より前 | F7: TRUE | G7: =ランキング1000曲!E12 -> 5級 | H7: =ランキング1000曲!G12 -> https://www.uta-net.com/song/65511/
A8: 15 | B8: 奏(かなで) | C8: スキマスイッチ | D8: 38056 | E8: 2010年より前 | F8: TRUE | G8: =ランキング1000曲!E21 -> 5級 | H8: =ランキング1000曲!G21 -> https://www.uta-net.com/song/18718/
A9: 18 | B9: 小さな恋のうた | C9: MONGOL800 | D9: 37150 | E9: 2010年より前 | F9: TRUE | G9: =ランキング1000曲!E24 -> 5級 | H9: =ランキング1000曲!G24 -> https://www.uta-net.com/song/48901/
A10: 30 | B10: HANABI | C10: Mr.Children | D10: 39694 | E10: 2010年より前 | F10: TRUE | G10: =ランキング1000曲!E36 -> 5級 | H10: =ランキング1000曲!G36 -> https://www.uta-net.com/song/70478/
A11: 34 | B11: 糸 | C11: 中島みゆき | D11: 37034 | E11: 2010年より前 | F11: TRUE | G11: =ランキング1000曲!E40 -> 5級 | H11: =ランキング1000曲!G40 -> https://www.uta-net.com/song/10225/
A12: 37 | B12: 3月9日 | C12: レミオロメン | D12: 38055 | E12: 2010年より前 | F12: TRUE | G12: =ランキング1000曲!E43 -> 5級 | H12: =ランキング1000曲!G43 -> https://www.uta-net.com/song/18874/
A13: 39 | B13: チェリー | C13: スピッツ | D13: 35165 | E13: 2010年より前 | F13: TRUE | G13: =ランキング1000曲!E45 -> 5級 | H13: =ランキング1000曲!G45 -> https://www.uta-net.com/song/9073/
A14: 52 | B14: サウダージ | C14: ポルノグラフィティ | D14: 36782 | E14: 2010年より前 | F14: TRUE | G14: =ランキング1000曲!E58 -> 5級 | H14: =ランキング1000曲!G58 -> https://www.uta-net.com/song/12513/
A15: 56 | B15: うれしいひなまつり | C15: 童謡・唱歌 | D15: 38987 | E15: 2010年より前 | F15: FALSE | G15: =ランキング1000曲!E62 -> 5級 | H15: =ランキング1000曲!G62 -> https://www.uta-net.com/song/13930/
A16: 62 | B16: 愛のかたまり | C16: DOMOTO | D16: 37209 | E16: 2010年より前 | F16: TRUE | G16: =ランキング1000曲!E68 -> 5級 | H16: =ランキング1000曲!G68 -> https://www.uta-net.com/song/15597/
A17: 63 | B17: YELL | C17: いきものがかり | D17: 40079 | E17: 2010年より前 | F17: TRUE | G17: =ランキング1000曲!E69 -> 5級 | H17: =ランキング1000曲!G69 -> https://www.uta-net.com/song/84214/
A18: 68 | B18: アンパンマンのマーチ | C18: ドリーミング | D18: 39072 | E18: 2010年より前 | F18: FALSE | G18: =ランキング1000曲!E74 -> 5級 | H18: =ランキング1000曲!G74 -> https://www.uta-net.com/song/7326/
A19: 69 | B19: 手紙 ～拝啓 十五の君へ～ | C19: アンジェラ・アキ | D19: 39708 | E19: 2010年より前 | F19: TRUE | G19: =ランキング1000曲!E75 -> 5級 | H19: =ランキング1000曲!G75 -> https://www.uta-net.com/song/70553/
A20: 71 | B20: ブルーバード | C20: いきものがかり | D20: 39638 | E20: 2010年より前 | F20: TRUE | G20: =ランキング1000曲!E77 -> 5級 | H20: =ランキング1000曲!G77 -> https://www.uta-net.com/song/66961/
A21: 76 | B21: 栄光の架橋 | C21: ゆず | D21: 38190 | E21: 2010年より前 | F21: TRUE | G21: =ランキング1000曲!E82 -> 5級 | H21: =ランキング1000曲!G82 -> https://www.uta-net.com/song/19425/
A22: 78 | B22: さくら(独唱) | C22: 森山直太朗 | D22: 37531 | E22: 2010年より前 | F22: TRUE | G22: =ランキング1000曲!E84 -> 5級 | H22: =ランキング1000曲!G84 -> https://www.uta-net.com/song/17129/
A23: 80 | B23: 遥か | C23: GReeeeN | D23: 39960 | E23: 2010年より前 | F23: TRUE | G23: =ランキング1000曲!E86 -> 5級 | H23: =ランキング1000曲!G86 -> https://www.uta-net.com/song/80054/
A24: 83 | B24: Love so sweet | C24: 嵐 | D24: 39134 | E24: 2010年より前 | F24: TRUE | G24: =ランキング1000曲!E89 -> 5級 | H24: =ランキング1000曲!G89 -> https://www.uta-net.com/song/51913/
A25: 84 | B25: me me she | C25: RADWIMPS | D25: 39057 | E25: 2010年より前 | F25: TRUE | G25: =ランキング1000曲!E90 -> 5級 | H25: =ランキング1000曲!G90 -> https://www.uta-net.com/song/49383/
A26: 89 | B26: 愛唄 | C26: GReeeeN | D26: 39218 | E26: 2010年より前 | F26: TRUE | G26: =ランキング1000曲!E95 -> 5級 | H26: =ランキング1000曲!G95 -> https://www.uta-net.com/song/53277/
A27: 91 | B27: 道 | C27: EXILE | D27: 39127 | E27: 2010年より前 | F27: TRUE | G27: =ランキング1000曲!E97 -> 5級 | H27: =ランキング1000曲!G97 -> https://www.uta-net.com/song/51644/
A28: 92 | B28: One Love | C28: 嵐 | D28: 39624 | E28: 2010年より前 | F28: TRUE | G28: =ランキング1000曲!E98 -> 5級 | H28: =ランキング1000曲!G98 -> https://www.uta-net.com/song/67818/
A29: 93 | B29: A・RA・SHI | C29: 嵐 | D29: 36467 | E29: 2010年より前 | F29: TRUE | G29: =ランキング1000曲!E99 -> 5級 | H29: =ランキング1000曲!G99 -> https://www.uta-net.com/song/12167/
A30: 95 | B30: 三日月 | C30: 絢香 | D30: 38987 | E30: 2010年より前 | F30: TRUE | G30: =ランキング1000曲!E101 -> 5級 | H30: =ランキング1000曲!G101 -> https://www.uta-net.com/song/45078/
A31: 98 | B31: NAO | C31: HY | D31: 38819 | E31: 2010年より前 | F31: FALSE | G31: =ランキング1000曲!E104 -> 5級 | H31: =ランキング1000曲!G104 -> https://www.uta-net.com/song/40362/
A32: 100 | B32: Story | C32: AI | D32: 38490 | E32: 2010年より前 | F32: TRUE | G32: =ランキング1000曲!E106 -> 5級 | H32: =ランキング1000曲!G106 -> https://www.uta-net.com/song/25996/
A33: 102 | B33: 愛をこめて花束を | C33: Superfly | D33: 39505 | E33: 2010年より前 | F33: TRUE | G33: =ランキング1000曲!E108 -> 4級 | H33: =ランキング1000曲!G108 -> https://www.uta-net.com/song/60335/
A34: 105 | B34: 木綿のハンカチーフ | C34: 太田裕美 | D34: 34243 | E34: 2010年より前 | F34: TRUE | G34: =ランキング1000曲!E111 -> 4級 | H34: =ランキング1000曲!G111 -> https://www.uta-net.com/song/4548/
A35: 106 | B35: 全力少年 | C35: スキマスイッチ | D35: 38462 | E35: 2010年より前 | F35: TRUE | G35: =ランキング1000曲!E112 -> 4級 | H35: =ランキング1000曲!G112 -> https://www.uta-net.com/song/25879/
A36: 113 | B36: COSMOS | C36: 合唱 | D36: 38337 | E36: 2010年より前 | F36: FALSE | G36: =ランキング1000曲!E119 -> 4級 | H36: =ランキング1000曲!G119 -> https://www.uta-net.com/song/117619/
A37: 114 | B37: 未来予想図II | C37: DREAMS COME TRUE | D37: 32834 | E37: 2010年より前 | F37: TRUE | G37: =ランキング1000曲!E120 -> 4級 | H37: =ランキング1000曲!G120 -> https://www.uta-net.com/song/4388/
A38: 119 | B38: ふたりごと | C38: RADWIMPS | D38: 38854 | E38: 2010年より前 | F38: FALSE | G38: =ランキング1000曲!E125 -> 4級 | H38: =ランキング1000曲!G125 -> https://www.uta-net.com/song/42155/
A39: 122 | B39: 天体観測 | C39: BUMP OF CHICKEN | D39: 36964 | E39: 2010年より前 | F39: TRUE | G39: =ランキング1000曲!E128 -> 4級 | H39: =ランキング1000曲!G128 -> https://www.uta-net.com/song/12840/
A40: 125 | B40: 赤い糸 | C40: コブクロ | D40: 39750 | E40: 2010年より前 | F40: FALSE | G40: =ランキング1000曲!E131 -> 4級 | H40: =ランキング1000曲!G131 -> https://www.uta-net.com/song/58228/
A41: 127 | B41: Butterfly | C41: 木村カエラ | D41: 39988 | E41: 2010年より前 | F41: TRUE | G41: =ランキング1000曲!E133 -> 4級 | H41: =ランキング1000曲!G133 -> https://www.uta-net.com/song/80300/
A42: 133 | B42: 旅立ちの日に | C42: 合唱 | D42: 38483 | E42: 2010年より前 | F42: FALSE | G42: =ランキング1000曲!E139 -> 4級 | H42: =ランキング1000曲!G139 -> https://www.uta-net.com/song/159065/
...

Sheet ランキング1000曲
B2: 歌ネット 歴代人気順1〜1000位 | J2: 対象曲 | K2: 1000
B3: 出典：https://www.uta-net.com/ranking/total/?sort=pop-d | J3: 採用候補 | K3: =COUNTIFS(F7:F1006,"採用候補") -> 545
B4: 取得日：2026/10/13。2010年以降を採用候補。段位は元順位100位ごとの仮配分。 | J4: 除外 | K4: =COUNTIFS(F7:F1006,"除外") -> 455
A6: 元順位 | B6: 曲名 | C6: アーティスト | D6: 掲載発売日 | E6: 段位候補 | F6: 日付による選定 | G6: 曲ページ | H6: 歌詞表示回数
A7: 1 | B7: クリスマスソング | C7: back number | D7: 42326 | E7: =CHOOSE(INT((A7-1)/100)+1,"5級","4級","3級","2級","1級","初段","二段","三段","四段","五段") -> 5級 | F7: =IF(D7>=DATE(2010,1,1),"採用候補","除外") -> 採用候補 | G7: https://www.uta-net.com/song/195484/ | H7: 13793181
A8: 2 | B8: Lemon | C8: 米津玄師 | D8: 43173 | E8: =CHOOSE(INT((A8-1)/100)+1,"5級","4級","3級","2級","1級","初段","二段","三段","四段","五段") -> 5級 | F8: =IF(D8>=DATE(2010,1,1),"採用候補","除外") -> 採用候補 | G8: https://www.uta-net.com/song/244127/ | H8: 13479322
A9: 3 | B9: Bling-Bang-Bang-Born | C9: Creepy Nuts | D9: 45298 | E9: =CHOOSE(INT((A9-1)/100)+1,"5級","4級","3級","2級","1級","初段","二段","三段","四段","五段") -> 5級 | F9: =IF(D9>=DATE(2010,1,1),"採用候補","除外") -> 採用候補 | G9: https://www.uta-net.com/song/348673/ | H9: 9317438
A10: 4 | B10: 花束 | C10: back number | D10: 40716 | E10: =CHOOSE(INT((A10-1)/100)+1,"5級","4級","3級","2級","1級","初段","二段","三段","四段","五段") -> 5級 | F10: =IF(D10>=DATE(2010,1,1),"採用候補","除外") -> 採用候補 | G10: https://www.uta-net.com/song/113824/ | H10: 8240970
A11: 5 | B11: 366日 | C11: HY | D11: 43334 | E11: =CHOOSE(INT((A11-1)/100)+1,"5級","4級","3級","2級","1級","初段","二段","三段","四段","五段") -> 5級 | F11: =IF(D11>=DATE(2010,1,1),"採用候補","除外") -> 採用候補 | G11: https://www.uta-net.com/song/64011/ | H11: 8159653
A12: 6 | B12: キセキ | C12: GReeeeN | D12: 39596 | E12: =CHOOSE(INT((A12-1)/100)+1,"5級","4級","3級","2級","1級","初段","二段","三段","四段","五段") -> 5級 | F12: =IF(D12>=DATE(2010,1,1),"採用候補","除外") -> 除外 | G12: https://www.uta-net.com/song/65511/ | H12: 7942013
A13: 7 | B13: Pretender | C13: Official髭男dism | D13: 43600 | E13: =CHOOSE(INT((A13-1)/100)+1,"5級","4級","3級","2級","1級","初段","二段","三段","四段","五段") -> 5級 | F13: =IF(D13>=DATE(2010,1,1),"採用候補","除外") -> 採用候補 | G13: https://www.uta-net.com/song/266648/ | H13: 7537932
A14: 8 | B14: 前前前世 (movie ver.) | C14: RADWIMPS | D14: 42606 | E14: =CHOOSE(INT((A14-1)/100)+1,"5級","4級","3級","2級","1級","初段","二段","三段","四段","五段") -> 5級 | F14: =IF(D14>=DATE(2010,1,1),"採用候補","除外") -> 採用候補 | G14: https://www.uta-net.com/song/211495/ | H14: 7291419
A15: 9 | B15: RPG | C15: SEKAI NO OWARI | D15: 41395 | E15: =CHOOSE(INT((A15-1)/100)+1,"5級","4級","3級","2級","1級","初段","二段","三段","四段","五段") -> 5級 | F15: =IF(D15>=DATE(2010,1,1),"採用候補","除外") -> 採用候補 | G15: https://www.uta-net.com/song/145480/ | H15: 6354753
A16: 10 | B16: LOSER | C16: 米津玄師 | D16: 42641 | E16: =CHOOSE(INT((A16-1)/100)+1,"5級","4級","3級","2級","1級","初段","二段","三段","四段","五段") -> 5級 | F16: =IF(D16>=DATE(2010,1,1),"採用候補","除外") -> 採用候補 | G16: https://www.uta-net.com/song/215594/ | H16: 6149984
A17: 11 | B17: ハッピーエンド | C17: back number | D17: 42690 | E17: =CHOOSE(INT((A17-1)/100)+1,"5級","4級","3級","2級","1級","初段","二段","三段","四段","五段") -> 5級 | F17: =IF(D17>=DATE(2010,1,1),"採用候補","除外") -> 採用候補 | G17: https://www.uta-net.com/song/216847/ | H17: 6107928
A18: 12 | B18: 紅蓮華 | C18: LiSA | D18: 43649 | E18: =CHOOSE(INT((A18-1)/100)+1,"5級","4級","3級","2級","1級","初段","二段","三段","四段","五段") -> 5級 | F18: =IF(D18>=DATE(2010,1,1),"採用候補","除外") -> 採用候補 | G18: https://www.uta-net.com/song/270036/ | H18: 5802439
... A1006: 1000 | B1006: Who... | C1006: 浜崎あゆみ | D1006: 36474 | E1006: =CHOOSE(INT((A1006-1)/100)+1,"5級","4級","3級","2級","1級","初段","二段","三段","四段","五段") -> 五段 | F1006: =IF(D1006>=DATE(2010,1,1),"採用候補","除外") -> 除外 | G1006: https://www.uta-net.com/song/12836/ | H1006: 845137
